Workbook

Sheet INV
D3: COMMERCIAL INVOICE
A7: Hangzhou HS Fashion International Ltd NO.1 Yaojia Road,Liangzhu Street, Yuhang District, Hangzhou , China 311112
A9: Tel: 0086 571 8676 8011
A10: Fax:0086 571 8676 8008
A11: EMAIL:vivian.jin@hsfashion.cn
A13: SOLD TO: | G13: DATE: | H13: 46187
A14: WHITE STUFF LTD | G14: INVOICE NO.: | H14: 26HT1205010A
A15: CANTERBURY COURT | G15: PAYMENT TERM: | H15: T/T AFTER 90 DAYS
A16: 1-3 BRIXTON ROAD | G16: SHIPMENT TERM: | H16: BY SEA
A17: LONDON | G17: SHIPMENT DATE: | H17: 46193
A18: SW9 6DE | G18: INCOTERMS | H18: FOB SHANGHAI
A19: UK
A20: VAT NUMBER: | B20: GB 974972851
A25: STYLE | B25: PO | C25: DOCKET | D25: DESCRIPTION | H25: QUANTITY(PCS) | I25: UNIT PRICE (USD) | J25: TOTAL (USD)
A26: 447310 | B26: PO00074648 | C26: 20000 | D26: LADIES' 100%RECYCLED POLYESTER KNITTED TOP BORG ZIP THROUGH | H26: ='PL-Home Shopping'!F40 -> 1543 | I26: 20.4 | J26: =H26*I26 -> 31477.2
A30: TOTAL: | H30: =SUM(H26:H28) -> 1543 | J30: =SUM(J26:J28) -> 31477.2
A32: =G175&"ONLY"&"(IN US DOLLARS)" -> SAY TOTAL THIRTY ONE THOUSAND FOUR HUNDRED SEVENTY SEVEN AND CENTS TWENTY ONLY(IN US DOLLARS)
A37: DELIVERY ADDRESS: | G37: TOTAL CARTONS: | I37: ='PL-Home Shopping'!F41 -> 201
A38: White Stuff Warehouse | G38: TOTAL NET WEIGHT: | I38: ='PL-Home Shopping'!F43 -> 1306.5
A39: Unit 4 Thorpe Way | G39: TOTAL GROSS WEIGHT: | I39: ='PL-Home Shopping'!F42 -> 1507.5
A40: Leicester, LE19 1SU | G40: DIMENSIONS: | I40: 60*40*30CM
A41: UNITED KINGDOM
A44: Beneficiary Bank: | B44: HUA XIA BANK
B45: Swift BIC:HXBKCNBJ020
B46: Address:INT'L DEPT, 33/F, BUILDING 2, OCEANWIDE INT'L CENTRE, NO.2 XIANGZHANG STREET, JIANGGAN DISTRICT, HANGZHOU, ZHEJIANG, CHINA
A47: Beneficiary: | B47: Name:Hangzhou HS Fashion International Ltd
B48: Address: NO.1 Yaojia Road,Liangzhu Street, Yuhang District, Hangzhou , China
B49: City,Province:Hangzhou,Zhejiang
B50: A/C. No.:10458000000579668
A51: Intermediary Bank: | B51: Jpmorgan Chase bank,New York
B52: Swift BIC: A/C no.1002198(UID220613), Swift: BKCHUS33 | C52: CHASUS33XXX
A53: Account with Bank: | B53: HUA XIA BANK
B54: A/C. No.:10458000000579668
B55: Swift BIC:HXBKCNBJ020
A56: Be reminded that we will never request changing our banking account by Email, Please phone me immediately if you receive this kind of email
A57: Contact to:Vivian.Jin T: 0571-86768000*8304 M: +86 13758226346
A164: =J30 -> 31477.2
G165: =INT(INT(A164)/1000000) -> 0 | H165: =INT((RIGHT(INT(A164),6))/100000) -> 0 | I165: =INT((RIGHT(INT(A164),5))/1000) -> 31 | J165: =INT((RIGHT(INT(A164),3))/100) -> 4 | K165: =INT(RIGHT(INT(A164),2)) -> 77 | L165: =ROUND((A164*100-INT(A164)*100),0) -> 20
G166: =VLOOKUP(G165,$A165:$C293,2) -> ZERO | H166: =VLOOKUP(H165,$A166:$C293,2) -> ZERO | I166: =VLOOKUP(I165,$A166:$C293,2) -> THIRTY ONE | J166: =VLOOKUP(J165,$A166:$C293,2) -> FOUR | K166: =VLOOKUP(K165,$A166:$C293,2) -> SEVENTY SEVEN | L166: =VLOOKUP(L165,$A166:$C293,2) -> TWENTY
G167: SAY TOTAL
...

Sheet PL-Home Shopping
A1: Packing List
A2: EXPORTER : | H2: INV NO: | I2: =INV!H14 -> 26HT1205010A | S2: DATE: | T2: =INV!H13 -> 46187
A3: SUPPLIER NAME : | C3: Hangzhou HS Fashion International Ltd | H3: P.O NO: | I3: =INV!B26 -> PO00074648 | S3: HS CODE: | T3: 6102300000
A4: SUPPLIER ADDRESS : | H4: BUYER (IF OTHER THAN CONSIGNEE)
A5: NO.1 Yaojia Road,Liangzhu Street, Yuhang District, Hangzhou , China 311112
A6: CONSIGNEE :
A7: M/S. WHITE STUFF LTD. CANTERBURY COURT, 1-3 BRIXTON ROAD LONDON SW9, 6DE U.K | H7: OTHER REFERENCE:
H8: COUNTRY OF ORIGIN OF | L8: COUNTRY OF DESTINATION
H9: CHINA | L9: United Kingdom & The European Union (EU)
A10: PRE- CARRIAGE BY : | D10: SEA | H10: PLACE OF RECIEPRT BY PRE-CARRIER
A11: VESSEL / FLIGHT NO.: | D11: MSC FATMA QB624W | H11: PORT OF LOADING | I11: SHANGHAI
A12: PORT OF DISCHARGE : | D12: FELIXSTOWE | H12: FINAL PLACE OF DELIVERY | L12: United Kingdom & The European Union (EU) | S12: ORIGIN CRITERION REFERENCES | U12: N/A
A13: ="Style - "&INV!A26 -> Style - 447310 | H13: UK PREFERNTIAL CODE | L13: =IF(I2="","",I2) -> 26HT1205010A | S13: EU REX NO (PREFERNTIAL)
A14: CHANNEL: | C14: Home Shopping | D14: ="ORDER NO"&" - "&I3 -> ORDER NO - PO00074648 | H14: SIZES
A16: CTNS NOS. | D16: NO. OF CARTONS | E16: COLOUR | G16: DOCKET NO. | H16: XXS | I16: XS | J16: S | K16: M | L16: L | M16: XL | N16: XXL | S16: PCS (UK) | T16: PCS (EU) | U16: TOTAL PCS | V16: GROSS WT | W16: NET WT | X16: CBM
A17: 1 | B17: =IF(A17="","","TO") -> TO | C17: 11 | D17: =C17-A17+1 -> 11 | E17: NAVY MULTI | G17: 20000 | I17: 8 | S17: =IF(A17="","",ROUNDUP(SUM(U17/2),0)) -> 44 | T17: =IF(A17="","",ROUNDDOWN(SUM(U17/2),0)) -> 44 | U17: =IF(D17="","",SUM(SUM(H17:R17)*D17)) -> 88 | V17: 7.5 | W17: 6.5 | X17: 60*40*30
A18: 12 | B18: =IF(A18="","","TO") -> TO | C18: 48 | D18: =C18-A18+1 -> 37 | E18: NAVY MULTI | G18: 20000 | J18: 8 | S18: =IF(A18="","",ROUNDUP(SUM(U18/2),0)) -> 148 | T18: =IF(A18="","",ROUNDDOWN(SUM(U18/2),0)) -> 148 | U18: =IF(D18="","",SUM(SUM(H18:R18)*D18)) -> 296 | V18: 7.5 | W18: 6.5 | X18: 60*40*30
A19: 49 | B19: =IF(A19="","","TO") -> TO | C19: 136 | D19: =C19-A19+1 -> 88 | E19: NAVY MULTI | G19: 20000 | K19: 8 | S19: =IF(A19="","",ROUNDUP(SUM(U19/2),0)) -> 352 | T19: =IF(A19="","",ROUNDDOWN(SUM(U19/2),0)) -> 352 | U19: =IF(D19="","",SUM(SUM(H19:R19)*D19)) -> 704 | V19: 7.5 | W19: 6.5 | X19: 60*40*30
A20: 137 | B20: =IF(A20="","","TO") -> TO | C20: 190 | D20: =C20-A20+1 -> 54 | E20: NAVY MULTI | G20: 20000 | L20: 7 | S20: =IF(A20="","",ROUNDUP(SUM(U20/2),0)) -> 189 | T20: =IF(A20="","",ROUNDDOWN(SUM(U20/2),0)) -> 189 | U20: =IF(D20="","",SUM(SUM(H20:R20)*D20)) -> 378 | V20: 7.5 | W20: 6.5 | X20: 60*40*30
A21: 191 | B21: =IF(A21="","","TO") -> TO | C21: 197 | D21: =C21-A21+1 -> 7 | E21: NAVY MULTI | G21: 20000 | M21: 7 | S21: =IF(A21="","",ROUNDUP(SUM(U21/2),0)) -> 25 | T21: =IF(A21="","",ROUNDDOWN(SUM(U21/2),0)) -> 24 | U21: =IF(D21="","",SUM(SUM(H21:R21)*D21)) -> 49 | V21: 7.5 | W21: 6.5 | X21: 60*40*30
A22: 198 | B22: =IF(A22="","","TO") -> TO | C22: 199 | D22: =C22-A22+1 -> 2 | E22: NAVY MULTI | G22: 20000 | N22: 7 | S22: =IF(A22="","",ROUNDUP(SUM(U22/2),0)) -> 7 | T22: =IF(A22="","",ROUNDDOWN(SUM(U22/2),0)) -> 7 | U22: =IF(D22="","",SUM(SUM(H22:R22)*D22)) -> 14 | V22: 7.5 | W22: 6.5 | X22: 60*40*30
A23: 200 | B23: =IF(A23="","","TO") -> TO | C23: 200 | D23: =C23-A23+1 -> 1 | E23: NAVY MULTI | G23: 20000 | I23: 5 | L23: 2 | S23: =IF(A23="","",ROUNDUP(SUM(U23/2),0)) -> 4 | T23: =IF(A23="","",ROUNDDOWN(SUM(U23/2),0)) -> 3 | U23: =IF(D23="","",SUM(SUM(H23:R23)*D23)) -> 7 | V23: 7.5 | W23: 6.5 | X23: 60*40*30
A24: 201 | B24: =IF(A24="","","TO") -> TO | C24: 201 | D24: =C24-A24+1 -> 1 | E24: NAVY MULTI | G24: 20000 | J24: 1 | K24: 1 | M24: 1 | N24: 4 | S24: =IF(A24="","",ROUNDUP(SUM(U24/2),0)) -> 4 | T24: =IF(A24="","",ROUNDDOWN(SUM(U24/2),0)) -> 3 | U24: =IF(D24="","",SUM(SUM(H24:R24)*D24)) -> 7 | V24: 7.5 | W24: 6.5 | X24: 60*40*30
B26: =IF(A26="","","TO") | S26: =IF(A26="","",ROUNDUP(SUM(U26/2),0)) | T26: =IF(A26="","",ROUNDDOWN(SUM(U26/2),0)) | U26: =IF(D26="","",SUM(SUM(H26:R26)*D26))
B27: =IF(A27="","","TO") | D27: =IF(A27="","",SUM(C27-A27+1)) | E27: =IF(A27="","",E26) | S27: =IF(A27="","",ROUNDUP(SUM(U27/2),0)) | T27: =IF(A27="","",ROUNDDOWN(SUM(U27/2),0)) | U27: =IF(D27="","",SUM(SUM(H27:R27)*D27))
D28: =IF(A28="","",SUM(C28-A28+1)) | O28: TOTAL PCS | S28: =SUM(S17:S27) -> 773 | T28: =SUM(T17:T27) -> 770 | U28: =SUM(U16:U27) -> 1543 | V28: =SUMPRODUCT(V17:V27,$D$17:$D$27) -> 1507.5 | W28: =SUMPRODUCT(W17:W27,$D$17:$D$27) -> 1306.5 | X28: =ROUND(0.6*0.4*0.3*D30,2) -> 14.47
B30: TOTAL CTNS | D30: =SUM(D17:D28) -> 201 | O30: TOTAL PCS | S30: =S28 -> 773 | T30: =T28 -> 770 | U30: =U28 -> 1543 | V30: =V28 -> 1507.5 | W30: =W28 -> 1306.5 | X30: =X28 -> 14.47
A31: SUMMARY | H31: SIZES
A32: CHANNEL | C32: DESCRIPTI ONS | D32: ORDER NOS. | E32: COLOUR | G32: DOCKET NO. | H32: =IF(H16="","",H16) -> XXS | I32: =IF(I16="","",I16) -> XS | J32: =IF(J16="","",J16) -> S | K32: =IF(K16="","",K16) -> M | L32: =IF(L16="","",L16) -> L | M32: =IF(M16="","",M16) -> XL | N32: =IF(N16="","",N16) -> XXL | O32: =IF(O16="","",O16) | ... R32: =IF(R16="","",R16) | S32: TOTAL PCS | U32: PO WISE TOTAL | V32: GWT KGS | W32: NWT KGS | X32: CBM
A33: =C14 -> Home Shopping | C33: BORG ZIP THROUGH | D33: =I3 -> PO00074648 | E33: =E17 -> NAVY MULTI | G33: =G17 -> 20000 | H33: =IF(SUM(H17:H27)=0,"",SUMPRODUCT(H17:H27,$D$17:$D$27)) | I33: =IF(SUM(I17:I27)=0,"",SUMPRODUCT(I17:I27,$D$17:$D$27)) -> 93 | J33: =IF(SUM(J17:J27)=0,"",SUMPRODUCT(J17:J27,$D$17:$D$27)) -> 297 | K33: =IF(SUM(K17:K27)=0,"",SUMPRODUCT(K17:K27,$D$17:$D$27)) -> 705 | L33: =IF(SUM(L17:L27)=0,"",SUMPRODUCT(L17:L27,$D$17:$D$27)) -> 380 | M33: =IF(SUM(M17:M27)=0,"",SUMPRODUCT(M17:M27,$D$17:$D$27)) -> 50 | N33: =IF(SUM(N17:N27)=0,"",SUMPRODUCT(N17:N27,$D$17:$D$27)) -> 18 | O33: =IF(SUM(O17:O27)=0,"",SUMPRODUCT(O17:O27,$D$17:$D$27)) | ... R33: =IF(SUM(R17:R27)=0,"",SUMPRODUCT(R17:R27,$D$17:$D$27)) | S33: =IF(SUM(U17:U27)=0,"",SUM(U17:U27)) -> 1543 | U33: =IF(SUM(U17:U27)=0,"",SUM(U17:U27)) -> 1543 | V33: =V30 -> 1507.5 | W33: =W30 -> 1306.5 | X33: =X30 -> 14.47
A35: =IF(L13="","",CONCATENATE("The exporter "&C3&" of the products covered by Invoice "&I2&" Date "&TEXT(T2,"DD/MM/YYYY")&" declares that, except where otherwise clearly indicated,"&"these products are of "&H9&" Preferential Origin according to rules of origin of the Developing Countries Trading Scheme of the U.K")) -> The exporter Hangzhou HS Fashion International Ltd of the products covered by Invoice 26HT1205010A Date 14/06/2026 declares that, except where otherwise clearly indicated,these products are of CHINA Preferential Origin according to rules of origin of the Developing Countries Trading Scheme of the U.K
A37: =IF(U13="","",CONCATENATE("THE EXPORTER OF THE PRODUCTS COVERED BY THIS DOCUMENT REX NUMBER "&U13&" DECLARE THAT, EXCEPT WHERE OTHERWISE CLEARLY INDICATED, THESE PRODUCTS ARE OF "&H9&" PREFERENTIAL ORIGIN ACCORDING TO RULES OF ORIGIN OF THE EUROPEAN UNION AND THAT THE ORIGIN CRITERION MET IS '"&MID(U12,LEN(U12)-1,1)&"' "))
A39: CARTON DIMENTION : 60 X 40 X 30 CMS | E39: PKGS
D40: TOTAL PCS | F40: =U28 -> 1543 | H40: PCS
D41: TOTAL BOX | F41: =D30 -> 201 | H41: CTNS
D42: G.WT | F42: =V28 -> 1507.5 | H42: KGS
D43: N.WT | F43: =W28 -> 1306.5 | H43: KGS
