Workbook

Sheet INV
D3: COMMERCIAL INVOICE
A7: Hangzhou HS Fashion International Ltd NO.1 Yaojia Road,Liangzhu Street, Yuhang District, Hangzhou , China 311112
A9: Tel: 0086 571 8676 8011
A10: Fax:0086 571 8676 8008
A11: EMAIL:vivian.jin@hsfashion.cn
A13: SOLD TO: | G13: DATE: | H13: 46187
A14: WHITE STUFF LTD | G14: INVOICE NO.: | H14: 26HT1202010C
A15: CANTERBURY COURT | G15: PAYMENT TERM: | H15: T/T AFTER 90 DAYS
A16: 1-3 BRIXTON ROAD | G16: SHIPMENT TERM: | H16: BY SEA
A17: LONDON | G17: SHIPMENT DATE: | H17: 46193
A18: SW9 6DE | G18: INCOTERMS | H18: FOB SHANGHAI
A19: UK
A20: VAT NUMBER: | B20: GB 974972851
A25: STYLE | B25: PO | C25: DOCKET | D25: DESCRIPTION | H25: QUANTITY(PCS) | I25: UNIT PRICE (USD) | J25: TOTAL (USD)
A26: 446914 | B26: PO 00074681 | C26: 20000 | D26: LADIES' 50%RECYCLE POLY 46%WOOL 4%ACYLIC WOVEN BLAZER SASHA TWEEDY BLAZER | H26: ='PL-home shopping'!F53 -> 914 | I26: 23.3 | J26: =H26*I26 -> 21296.2
A30: TOTAL: | H30: =SUM(H26:H28) -> 914 | J30: =SUM(J26:J28) -> 21296.2
A32: =G175&"ONLY"&"(IN US DOLLARS)" -> SAY TOTAL TWENTY ONE THOUSAND TWO HUNDRED NINETY SIX AND CENTS TWENTY ONLY(IN US DOLLARS)
A37: DELIVERY ADDRESS: | G37: TOTAL CARTONS: | I37: ='PL-home shopping'!F54 -> 66
A38: White Stuff Warehouse | G38: TOTAL NET WEIGHT: | I38: ='PL-home shopping'!F56 -> 643.5
A39: Unit 4 Thorpe Way | G39: TOTAL GROSS WEIGHT: | I39: ='PL-home shopping'!F55 -> 709.5
A40: Leicester, LE19 1SU | G40: DIMENSIONS: | I40: 60*40*30CM
A41: UNITED KINGDOM
A44: Beneficiary Bank: | B44: HUA XIA BANK
B45: Swift BIC:HXBKCNBJ020
B46: Address:INT'L DEPT, 33/F, BUILDING 2, OCEANWIDE INT'L CENTRE, NO.2 XIANGZHANG STREET, JIANGGAN DISTRICT, HANGZHOU, ZHEJIANG, CHINA
A47: Beneficiary: | B47: Name:Hangzhou HS Fashion International Ltd
B48: Address: NO.1 Yaojia Road,Liangzhu Street, Yuhang District, Hangzhou , China
B49: City,Province:Hangzhou,Zhejiang
B50: A/C. No.:10458000000579668
A51: Intermediary Bank: | B51: Jpmorgan Chase bank,New York
B52: Swift BIC: A/C no.1002198(UID220613), Swift: BKCHUS33 | C52: CHASUS33XXX
A53: Account with Bank: | B53: HUA XIA BANK
B54: A/C. No.:10458000000579668
B55: Swift BIC:HXBKCNBJ020
A56: Be reminded that we will never request changing our banking account by Email, Please phone me immediately if you receive this kind of email
A57: Contact to:Vivian.Jin T: 0571-86768000*8304 M: +86 13758226346
A164: =J30 -> 21296.2
G165: =INT(INT(A164)/1000000) -> 0 | H165: =INT((RIGHT(INT(A164),6))/100000) -> 0 | I165: =INT((RIGHT(INT(A164),5))/1000) -> 21 | J165: =INT((RIGHT(INT(A164),3))/100) -> 2 | K165: =INT(RIGHT(INT(A164),2)) -> 96 | L165: =ROUND((A164*100-INT(A164)*100),0) -> 20
G166: =VLOOKUP(G165,$A165:$C293,2) -> ZERO | H166: =VLOOKUP(H165,$A166:$C293,2) -> ZERO | I166: =VLOOKUP(I165,$A166:$C293,2) -> TWENTY ONE | J166: =VLOOKUP(J165,$A166:$C293,2) -> TWO | K166: =VLOOKUP(K165,$A166:$C293,2) -> NINETY SIX | L166: =VLOOKUP(L165,$A166:$C293,2) -> TWENTY
G167: SAY TOTAL
...

Sheet PL-home shopping
A1: Packing List
A2: EXPORTER : | H2: INV NO: | I2: =INV!H14 -> 26HT1202010C | AF2: DATE: | AG2: =INV!H13 -> 46187
A3: SUPPLIER NAME : | C3: Hangzhou HS Fashion International Ltd | H3: P.O NO: | I3: =INV!B26 -> PO 00074681 | AF3: HS CODE: | AG3: 6204330000
A4: SUPPLIER ADDRESS : | H4: BUYER (IF OTHER THAN CONSIGNEE)
A5: NO.1 Yaojia Road,Liangzhu Street, Yuhang District, Hangzhou , China 311112
A6: CONSIGNEE :
A7: M/S. WHITE STUFF LTD. CANTERBURY COURT, 1-3 BRIXTON ROAD LONDON SW9, 6DE U.K | H7: OTHER REFERENCE:
H8: COUNTRY OF ORIGIN OF | L8: COUNTRY OF DESTINATION
H9: CHINA | L9: United Kingdom & The European Union (EU)
A10: PRE- CARRIAGE BY : | D10: SEA | H10: PLACE OF RECIEPRT BY PRE-CARRIER
A11: VESSEL / FLIGHT NO.: | D11: MSC FATMA QB624W | H11: PORT OF LOADING | I11: SHANGHAI
A12: PORT OF DISCHARGE : | D12: FELIXSTOWE | H12: FINAL PLACE OF DELIVERY | L12: United Kingdom & The European Union (EU) | AF12: ORIGIN CRITERION REFERENCES | AH12: N/A
A13: Style -446914 | H13: UK PREFERNTIAL CODE | L13: =IF(I2="","",I2) -> 26HT1202010C | AF13: EU REX NO (PREFERNTIAL)
A14: CHANNEL: | C14: home shopping | D14: ="ORDER NO"&" - "&I3 -> ORDER NO - PO 00074681 | H14: SIZES
A16: CTNS NOS. | D16: NO. OF CARTONS | E16: COLOUR | G16: DOCKET NO. | H16: 6P | I16: 8P | J16: 10P | K16: 12P | L16: 14P | M16: 16P | N16: 18P | O16: 6R | P16: 8R | Q16: 10R | R16: 12R | S16: 14R | T16: 16R | U16: 18R | V16: 20R | W16: 22R | X16: 24R | Y16: 6L | Z16: 8L | AA16: 10L | AB16: 12L | AC16: 14L | AD16: 16L | AE16: 18L | AF16: PCS (UK) | AG16: PCS (EU) | AH16: TOTAL PCS | AI16: GROSS WT | AJ16: NET WT | AK16: CBM
A17: 1 | B17: =IF(A17="","","TO") -> TO | C17: 1 | D17: =C17-A17+1 -> 1 | E17: PLUM MLT | G17: 20000 | H17: 7 | J17: 2 | L17: 5 | AF17: =IF(A17="","",ROUNDUP(SUM(AH17/2),0)) -> 7 | AG17: =IF(A17="","",ROUNDDOWN(SUM(AH17/2),0)) -> 7 | AH17: =IF(D17="","",SUM(SUM(H17:AE17)*D17)) -> 14 | AI17: 10.5 | AJ17: 9.5 | AK17: 60*40*30
A18: 2 | B18: =IF(A18="","","TO") -> TO | C18: 2 | D18: =C18-A18+1 -> 1 | E18: PLUM MLT | G18: 20000 | I18: 10 | N18: 4 | AF18: =IF(A18="","",ROUNDUP(SUM(AH18/2),0)) -> 7 | AG18: =IF(A18="","",ROUNDDOWN(SUM(AH18/2),0)) -> 7 | AH18: =IF(D18="","",SUM(SUM(H18:AE18)*D18)) -> 14 | AI18: 10 | AJ18: 9 | AK18: 60*40*30
A19: 3 | B19: =IF(A19="","","TO") -> TO | C19: 3 | D19: =C19-A19+1 -> 1 | E19: PLUM MLT | G19: 20000 | J19: 14 | AF19: =IF(A19="","",ROUNDUP(SUM(AH19/2),0)) -> 7 | AG19: =IF(A19="","",ROUNDDOWN(SUM(AH19/2),0)) -> 7 | AH19: =IF(D19="","",SUM(SUM(H19:AE19)*D19)) -> 14 | AI19: 10 | AJ19: 9 | AK19: 60*40*30
A20: 4 | B20: =IF(A20="","","TO") -> TO | C20: 4 | D20: =C20-A20+1 -> 1 | E20: PLUM MLT | G20: 20000 | K20: 14 | AF20: =IF(A20="","",ROUNDUP(SUM(AH20/2),0)) -> 7 | AG20: =IF(A20="","",ROUNDDOWN(SUM(AH20/2),0)) -> 7 | AH20: =IF(D20="","",SUM(SUM(H20:AE20)*D20)) -> 14 | AI20: 11 | AJ20: 10 | AK20: 60*40*30
A21: 5 | B21: =IF(A21="","","TO") -> TO | C21: 5 | D21: =C21-A21+1 -> 1 | E21: PLUM MLT | G21: 20000 | K21: 12 | AF21: =IF(A21="","",ROUNDUP(SUM(AH21/2),0)) -> 6 | AG21: =IF(A21="","",ROUNDDOWN(SUM(AH21/2),0)) -> 6 | AH21: =IF(D21="","",SUM(SUM(H21:AE21)*D21)) -> 12 | AI21: 10 | AJ21: 9 | AK21: 60*40*30
A22: 6 | B22: =IF(A22="","","TO") -> TO | C22: 6 | D22: =C22-A22+1 -> 1 | E22: PLUM MLT | G22: 20000 | L22: 14 | AF22: =IF(A22="","",ROUNDUP(SUM(AH22/2),0)) -> 7 | AG22: =IF(A22="","",ROUNDDOWN(SUM(AH22/2),0)) -> 7 | AH22: =IF(D22="","",SUM(SUM(H22:AE22)*D22)) -> 14 | AI22: 11 | AJ22: 10 | AK22: 60*40*30
A23: 7 | B23: =IF(A23="","","TO") -> TO | C23: 7 | D23: =C23-A23+1 -> 1 | E23: PLUM MLT | G23: 20000 | J23: 3 | M23: 11 | AF23: =IF(A23="","",ROUNDUP(SUM(AH23/2),0)) -> 7 | AG23: =IF(A23="","",ROUNDDOWN(SUM(AH23/2),0)) -> 7 | AH23: =IF(D23="","",SUM(SUM(H23:AE23)*D23)) -> 14 | AI23: 11 | AJ23: 10 | AK23: 60*40*30
A24: 8 | B24: =IF(A24="","","TO") -> TO | C24: 8 | D24: =C24-A24+1 -> 1 | E24: PLUM MLT | G24: 20000 | O24: 14 | AF24: =IF(A24="","",ROUNDUP(SUM(AH24/2),0)) -> 7 | AG24: =IF(A24="","",ROUNDDOWN(SUM(AH24/2),0)) -> 7 | AH24: =IF(D24="","",SUM(SUM(H24:AE24)*D24)) -> 14 | AI24: 10 | AJ24: 9 | AK24: 60*40*30
A25: 9 | B25: =IF(A25="","","TO") -> TO | C25: 13 | D25: =C25-A25+1 -> 5 | E25: PLUM MLT | G25: 20000 | P25: 14 | AF25: =IF(A25="","",ROUNDUP(SUM(AH25/2),0)) -> 35 | AG25: =IF(A25="","",ROUNDDOWN(SUM(AH25/2),0)) -> 35 | AH25: =IF(D25="","",SUM(SUM(H25:AE25)*D25)) -> 70 | AI25: 10 | AJ25: 9 | AK25: 60*40*30
A26: 14 | B26: =IF(A26="","","TO") -> TO | C26: 23 | D26: =C26-A26+1 -> 10 | E26: PLUM MLT | G26: 20000 | Q26: 14 | AF26: =IF(A26="","",ROUNDUP(SUM(AH26/2),0)) -> 70 | AG26: =IF(A26="","",ROUNDDOWN(SUM(AH26/2),0)) -> 70 | AH26: =IF(D26="","",SUM(SUM(H26:AE26)*D26)) -> 140 | AI26: 10 | AJ26: 9 | AK26: 60*40*30
A27: 24 | B27: =IF(A27="","","TO") -> TO | C27: 35 | D27: =C27-A27+1 -> 12 | E27: PLUM MLT | G27: 20000 | R27: 14 | AF27: =IF(A27="","",ROUNDUP(SUM(AH27/2),0)) -> 84 | AG27: =IF(A27="","",ROUNDDOWN(SUM(AH27/2),0)) -> 84 | AH27: =IF(D27="","",SUM(SUM(H27:AE27)*D27)) -> 168 | AI27: 11 | AJ27: 10 | AK27: 60*40*30
A28: 36 | B28: =IF(A28="","","TO") -> TO | C28: 46 | D28: =C28-A28+1 -> 11 | E28: PLUM MLT | G28: 20000 | S28: 14 | AF28: =IF(A28="","",ROUNDUP(SUM(AH28/2),0)) -> 77 | AG28: =IF(A28="","",ROUNDDOWN(SUM(AH28/2),0)) -> 77 | AH28: =IF(D28="","",SUM(SUM(H28:AE28)*D28)) -> 154 | AI28: 11 | AJ28: 10 | AK28: 60*40*30
A29: 47 | B29: =IF(A29="","","TO") -> TO | C29: 47 | D29: =C29-A29+1 -> 1 | E29: PLUM MLT | G29: 20000 | S29: 13 | AF29: =IF(A29="","",ROUNDUP(SUM(AH29/2),0)) -> 7 | AG29: =IF(A29="","",ROUNDDOWN(SUM(AH29/2),0)) -> 6 | AH29: =IF(D29="","",SUM(SUM(H29:AE29)*D29)) -> 13 | AI29: 11 | AJ29: 10 | AK29: 60*40*30
A30: 48 | B30: =IF(A30="","","TO") -> TO | C30: 55 | D30: =C30-A30+1 -> 8 | E30: PLUM MLT | G30: 20000 | T30: 14 | AF30: =IF(A30="","",ROUNDUP(SUM(AH30/2),0)) -> 56 | AG30: =IF(A30="","",ROUNDDOWN(SUM(AH30/2),0)) -> 56 | AH30: =IF(D30="","",SUM(SUM(H30:AE30)*D30)) -> 112 | AI30: 11.5 | AJ30: 10.5 | AK30: 60*40*30
A31: 56 | B31: =IF(A31="","","TO") -> TO | C31: 60 | D31: =C31-A31+1 -> 5 | E31: PLUM MLT | G31: 20000 | U31: 14 | AF31: =IF(A31="","",ROUNDUP(SUM(AH31/2),0)) -> 35 | AG31: =IF(A31="","",ROUNDDOWN(SUM(AH31/2),0)) -> 35 | AH31: =IF(D31="","",SUM(SUM(H31:AE31)*D31)) -> 70 | AI31: 11.5 | AJ31: 10.5 | AK31: 60*40*30
A32: 61 | B32: =IF(A32="","","TO") -> TO | C32: 61 | D32: =C32-A32+1 -> 1 | E32: PLUM MLT | G32: 20000 | V32: 14 | AF32: =IF(A32="","",ROUNDUP(SUM(AH32/2),0)) -> 7 | AG32: =IF(A32="","",ROUNDDOWN(SUM(AH32/2),0)) -> 7 | AH32: =IF(D32="","",SUM(SUM(H32:AE32)*D32)) -> 14 | AI32: 11.5 | AJ32: 10.5 | AK32: 60*40*30
A33: 62 | B33: =IF(A33="","","TO") -> TO | C33: 62 | D33: =C33-A33+1 -> 1 | E33: PLUM MLT | G33: 20000 | O33: 2 | V33: 11 | AF33: =IF(A33="","",ROUNDUP(SUM(AH33/2),0)) -> 7 | AG33: =IF(A33="","",ROUNDDOWN(SUM(AH33/2),0)) -> 6 | AH33: =IF(D33="","",SUM(SUM(H33:AE33)*D33)) -> 13 | AI33: 11 | AJ33: 10 | AK33: 60*40*30
A34: 63 | B34: =IF(A34="","","TO") -> TO | C34: 63 | D34: =C34-A34+1 -> 1 | E34: PLUM MLT | G34: 20000 | W34: 13 | AF34: =IF(A34="","",ROUNDUP(SUM(AH34/2),0)) -> 7 | AG34: =IF(A34="","",ROUNDDOWN(SUM(AH34/2),0)) -> 6 | AH34: =IF(D34="","",SUM(SUM(H34:AE34)*D34)) -> 13 | AI34: 12 | AJ34: 11 | AK34: 60*40*30
A35: 64 | B35: =IF(A35="","","TO") -> TO | C35: 64 | D35: =C35-A35+1 -> 1 | E35: PLUM MLT | G35: 20000 | P35: 7 | Q35: 5 | X35: 4 | AF35: =IF(A35="","",ROUNDUP(SUM(AH35/2),0)) -> 8 | AG35: =IF(A35="","",ROUNDDOWN(SUM(AH35/2),0)) -> 8 | AH35: =IF(D35="","",SUM(SUM(H35:AE35)*D35)) -> 16 | AI35: 11.5 | AJ35: 10.5 | AK35: 60*40*30
A36: 65 | B36: =IF(A36="","","TO") -> TO | C36: 65 | D36: =C36-A36+1 -> 1 | E36: PLUM MLT | G36: 20000 | R36: 5 | T36: 2 | U36: 5 | AF36: =IF(A36="","",ROUNDUP(SUM(AH36/2),0)) -> 6 | AG36: =IF(A36="","",ROUNDDOWN(SUM(AH36/2),0)) -> 6 | AH36: =IF(D36="","",SUM(SUM(H36:AE36)*D36)) -> 12 | AI36: 9.5 | AJ36: 8.5 | AK36: 60*40*30
A37: 66 | B37: =IF(A37="","","TO") -> TO | C37: 66 | D37: =C37-A37+1 -> 1 | E37: PLUM MLT | G37: 20000 | P37: 9 | AF37: =IF(A37="","",ROUNDUP(SUM(AH37/2),0)) -> 5 | AG37: =IF(A37="","",ROUNDDOWN(SUM(AH37/2),0)) -> 4 | AH37: =IF(D37="","",SUM(SUM(H37:AE37)*D37)) -> 9 | AI37: 7 | AJ37: 6 | AK37: 60*40*30
B39: =IF(A39="","","TO") | AF39: =IF(A39="","",ROUNDUP(SUM(AH39/2),0)) | AG39: =IF(A39="","",ROUNDDOWN(SUM(AH39/2),0)) | AH39: =IF(D39="","",SUM(SUM(H39:AE39)*D39))
B40: =IF(A40="","","TO") | D40: =IF(A40="","",SUM(C40-A40+1)) | E40: =IF(A40="","",E39) | AF40: =IF(A40="","",ROUNDUP(SUM(AH40/2),0)) | AG40: =IF(A40="","",ROUNDDOWN(SUM(AH40/2),0)) | AH40: =IF(D40="","",SUM(SUM(H40:AE40)*D40))
D41: =IF(A41="","",SUM(C41-A41+1)) | X41: TOTAL PCS | AB41: TOTAL PCS | AF41: =SUM(AF17:AF40) -> 459 | AG41: =SUM(AG17:AG40) -> 455 | AH41: =SUM(AH16:AH40) -> 914 | AI41: =SUMPRODUCT(AI17:AI40,$D$17:$D$40) -> 709.5 | AJ41: =SUMPRODUCT(AJ17:AJ40,$D$17:$D$40) -> 643.5 | AK41: =ROUND(0.072*D43,2) -> 4.75
B43: TOTAL CTNS | D43: =SUM(D17:D41) -> 66 | O43: TOTAL PCS | S43: TOTAL PCS | X43: TOTAL PCS | AB43: TOTAL PCS | AF43: =AF41 -> 459 | AG43: =AG41 -> 455 | AH43: =AH41 -> 914 | AI43: =AI41 -> 709.5 | AJ43: =AJ41 -> 643.5 | AK43: =AK41 -> 4.75
...
